Workbook

Sheet 填写说明（请仔细查阅！！！）
A2: 序号 | B2: 对应细项 | C2: 填写说明
A3: 1 | B3: 报价单命名 | C3: 项目名称+供应商简称+报价日期+项目总金额
A4: 2 | B4: 报价单提供格式 | C4: 电子表格版+盖章扫描件。 此报价单必须加盖印章（公章、合同专用章、报价专用章，其中优先选择公章）,根据询价单位要求提供盖章扫描件或原件。
A5: 3 | B5: 项目时间 | C5: 需填写已知的项目执行时间
A6: 4 | B6: 报价公司名称 | C6: 需填写供应商全称
A7: 5 | B7: 报价项目 | C7: 需与招采通知的项目名称一致。
A8: 6 | B8: 报价人姓名 | C8: 填写真实提供报价的人员姓名，需与身份证上姓名一致
A9: 7 | B9: 报价人联系电话 | C9: 填写手机号
A10: 8 | B10: 报价人邮箱 | C10: 填写正确邮箱信息，原则上要求使用供应商公司邮箱
A11: 9 | B11: 行数量 | C11: 行数量和信息，可以根据实际情况调整。
A12: 10 | B12: 年框编号 | C12: 非年度供应商不需要填写年框编号。
A13: 11 | B13: 一线&二线城市报价 | C13: 如项目仅为一线或二线城市，按照报价模板进行常规报价即可； 如一个整包项目里包含多城市报价，报名明细页分为一线&二线城市两个表。
A14: 12 | B14: sku | C14: 无需罗列全部签约sku价格，根据实际使用sku项进行填写
A15: 注意！！！ （1）报价严格按照SKU进行提报拆分，SKU号+SKU描述+SKU价格，三个必须严格统一，采购会严格复核。 （2）支付凭证最好为支付/打款记录，虚假凭证一经发现，永久停止合作
A16: 具体填写说明：“汇总页”以下各部分如果没有，可以在报价单中留白，但是不要删除。
A17: 1 | B17: 指定垫付部分 | C17: 如中途接到需求部门自行指定分包或垫付要求，需要同步告知招采，招采确认推进方式后再进行推进；
A18: 2 | B18: 场地租赁部分 | C18: （1）原则上，场地租赁费用等不由供应商垫付。场地公关报批等现金类小额支付，可由供应商垫付。 （2）如因特殊情况，经招采确认可由供应商支付，此部分需供应商明确场地名称，具体展会位置/酒店会议厅等、面积、使用时段等信息。
A19: 3 | B19: 场地杂项部分 | C19: （1）场地相关的水电网、施工证、停车费等，可根据实际项目情况由供应商垫付，提供相应的凭证。
A20: 4 | B20: 搭建物料及人员部分 | C20: （1）搭建物料部分明确材质、工艺、尺寸。如报价中计算损耗，需对损耗部分说明。 （2）搭建人工明确进场/撤场时间（以*月*日*点）、以及工时。 （3) 搭建运输：明确车型、距离。运输费用：需要提供支付凭证结算，如为搭建物料公司负责，需要提供现场带日期地点水印的车辆照片
A21: 5 | B21: AV设备及人员部分 | C21: （1）所有设备具体到最小单位并标明品牌型号。特殊不常用的非年框设备，需标明用途。 （2）所有AV相关的人工，明确工种、工时。
A22: 6 | B22: 第三方人员部分 | C22: （1）兼职、保安、礼仪、模特、演员、摄影、摄像等，工作的人数、时长。 （2）非年框等级的化妆师、搭配师、摄影摄像师、模特、秀导、主持人、演员等提供姓名及简介。 （3） 机票、酒店、交通费等，列明时间、地点、人次、费用（执行京东的项目，国内机票酒店原则上使用京东商旅）
A23: 7 | B23: 后勤杂项部分 | C23: （1）小物料（抽奖箱、水牌、画架、椅背贴、指示牌、桌卡等）、奖杯等明确材质、尺寸。 （2）快递费：京东的项目，原则上使用京东快递。
A24: 8 | B24: 视频部分 | C24: 写清楚视频的片长、大致类型，主要内容等。 严格按照SKU细项进行报价，框外内容请说明背景原因。
A25: 9 | B25: 创意策划执行部分 | C25: （1）执行人员差旅当地交通：需要提供凭证 （2）执行人员差旅当地餐补：需要提供凭证 （3）执行人员差旅住宿费用：需要提供凭证且严格按照标准进行费用提报，不能超标准！
A26: 10 | B26: 差旅部分 | C26: 原则上使用京东商旅，尤其是国内机票。 如未使用京东商旅，请在项目执行前与采购员确认。（京东人员差旅不允许由供应商支付）
A27: 11 | B27: 展品物流部分 | C27: （1）车辆租用：需要提供支付凭证结算 （2）运输费用：需要提供支付凭证结算
A28: 12 | B28: 其他部分 | C28: 根据实际情况填写，涉及到第三方的，均需列明详细信息。
A29: 13 | B29: 城市清单 | C29: 一线城市报价挡：4个，北京市，上海市，广州市，深圳市； 二线城市报价挡：45个，成都市，杭州市，武汉市，重庆市，南京市，天津市，苏州市，西安市，长沙市，沈阳市，青岛市，郑州市，大连市，东莞市，宁波市，厦门市，福州市，无锡市，合肥市，昆明市，哈尔滨市，济南市，佛山市，长春市，温州市，石家庄市，南宁市，常州市，泉州市，南昌市，贵阳市，太原市，烟台市，嘉兴市，南通市，金华市，珠海市，惠州市，徐州市，海口市，乌鲁木齐市，绍兴市，中山市，台州市，兰州市

Sheet 汇总页模板
A1: 报价阶段-投标阶段 | F1: 报价阶段-执行前定标阶段 | K1: 报价阶段-执行后结算阶段
A2: 报价项目 | B2: 图书开学季&9.2超品日 | F2: 报价项目 | G2: 图书开学季&9.2超品日 | K2: 报价项目 | L2: 图书开学季&9.2超品日
A3: 项目时间 | B3: 2025年8月30-31日 | F3: 项目时间 | G3: 2025年8月30-31日 | K3: 项目时间 | L3: 2025年8月30-31日
A4: 报价公司名称 | B4: 成都申逻商务信息咨询有限公司 | F4: 报价公司名称 | G4: 成都申逻商务信息咨询有限公司 | K4: 报价公司名称 | L4: 成都申逻商务信息咨询有限公司
A5: 各部分内容 | B5: 描述 | C5: 报价金额 | D5: 备注 | F5: 各部分内容 | G5: 描述 | H5: 报价金额 | I5: 备注 | K5: 各部分内容 | L5: 描述 | M5: 报价金额 | N5: 备注
A6: 指定垫付部分 | C6: 0 | D6: 需求部门指定垫付 | F6: 指定垫付部分 | H6: 0 | I6: 需求部门指定垫付 | K6: 指定垫付部分 | M6: 0 | N6: 需求部门指定垫付
A7: 场地租赁部分 | C7: 0 | D7: 场地租赁 | F7: 场地租赁部分 | H7: 0 | I7: 场地租赁 | K7: 场地租赁部分 | M7: 0 | N7: 场地租赁
A8: 场地杂项部分 | C8: 12000 | D8: 包含报批、安保、网络、水电等 | F8: 场地杂项部分 | H8: =明细页模板!X18 -> 2000 | I8: 包含报批、安保、网络、水电等 | K8: 场地杂项部分 | M8: =明细页模板!AN16 -> 2000 | N8: 包含报批、安保、网络、水电等
A9: 搭建物料及人员部分 | C9: 102573.2 | D9: 包含搭建制作物料、力工、水工、电工等 | F9: 搭建物料及人员部分 | H9: =明细页模板!X86 -> 63393.969 | I9: 包含搭建制作物料、力工、水工、电工等 | K9: 搭建物料及人员部分 | M9: =明细页模板!AN56 -> 63953.969 | N9: 包含搭建制作物料、力工、水工、电工等
A10: AV设备及人员部分 | C10: 9364.68 | D10: 包含视频、灯光、音频相关设备及配套人员等 | F10: AV设备及人员部分 | H10: =明细页模板!X93 -> 1600 | I10: 包含视频、灯光、音频相关设备及配套人员等 | K10: AV设备及人员部分 | M10: =明细页模板!AN59 -> 1600 | N10: 包含视频、灯光、音频相关设备及配套人员等
A11: 第三方人员部分 | C11: 12573.21 | D11: 包含主持人、礼仪、保安、摄影摄像等 | F11: 第三方人员部分 | H11: =明细页模板!X101 -> 12573.21 | I11: 包含主持人、礼仪、保安、摄影摄像等 | K11: 第三方人员部分 | M11: =明细页模板!AN71 -> 12553.21 | N11: 包含主持人、礼仪、保安、摄影摄像等
A12: 后勤杂项部分 | C12: 0 | D12: 包含小物料等 | F12: 后勤杂项部分 | H12: =明细页模板!X112 -> 11416 | I12: 包含小物料等 | K12: 后勤杂项部分 | M12: =明细页模板!AN88 -> 12013.56 | N12: 包含小物料等
A13: 视频部分 | C13: 0 | D13: 包含视频制作剪辑等 | F13: 视频部分 | H13: =明细页模板!X116 -> 0 | I13: 包含视频制作剪辑等 | K13: 视频部分 | M13: =明细页模板!AN92 -> 0 | N13: 包含视频制作剪辑等
A14: 创意策划执行部分 | C14: 8127.79 | D14: 包含主视觉涉及、延展、执行人员费用等 | F14: 创意策划执行部分 | H14: =明细页模板!X123 -> 7712.705 | I14: 包含主视觉涉及、延展、执行人员费用等 | K14: 创意策划执行部分 | M14: =明细页模板!AN97 -> 2186.44 | N14: 包含主视觉涉及、延展、执行人员费用等
A15: 差旅部分 | C15: 6000 | D15: 包含执行人员差旅等 | F15: 差旅部分 | H15: =明细页模板!X126 -> 4000 | I15: 包含执行人员差旅等 | K15: 差旅部分 | M15: =明细页模板!AN100 -> 2460 | N15: 包含执行人员差旅等
A16: 展品物流部分 | C16: 30000 | D16: 包含供应商安排车辆进行展品运输等 | F16: 展品物流部分 | H16: =明细页模板!X129 -> 3000 | I16: 包含供应商安排车辆进行展品运输等 | K16: 展品物流部分 | M16: =明细页模板!AN103 -> 308.2 | N16: 包含供应商安排车辆进行展品运输等
A17: 其他部分 | C17: 19416 | F17: 其他部分 | H17: =明细页模板!X132 -> 0 | K17: 其他部分 | M17: =明细页模板!AN106 -> 0
A18: 小计(一线城市) | C18: 48543.79 | D18: 包含北京、上海、广州、深圳 | F18: 小计(一线城市) | H18: =明细页模板!X133 -> 28128.705 | I18: 包含北京、上海、广州、深圳 | K18: 小计(一线城市) | M18: =明细页模板!AN107 -> 18968.2 | N18: 包含北京、上海、广州、深圳
A19: 小计(二线城市) | B19: 一线城市报价*90% | C19: 112059.98 | D19: 包含约定的45个二线城市 | F19: 小计(二线城市) | G19: 一线城市报价*90% | H19: =明细页模板!X134 -> 69810.462 | I19: 包含约定的45个二线城市 | K19: 小计(二线城市) | L19: 一线城市报价*90% | M19: =明细页模板!AN108 -> 70296.462 | N19: 包含约定的45个二线城市
A20: 服务费 | B20: 0.1 | C20: =(C18+C19)*B20 -> 16060.377 | F20: 服务费 | H20: =明细页模板!X135 -> 9793.9167 | K20: 服务费 | M20: =明细页模板!AN109 -> 8926.4662
A21: 税费 | B21: 0.06 | C21: =(C18+C19+C20)*B21 -> 10599.849 | F21: 税费 | H21: =明细页模板!X136 -> 6463.985 | K21: 税费 | M21: =明细页模板!AN110 -> 5891.4677
A22: 总价 | C22: =C18+C19+C20+C21 -> 187264 | F22: 总价 | H22: =明细页模板!X137 -> 114197.07 | K22: 总价 | M22: =明细页模板!AN111 -> 104082.6
A23: 优惠价 | F23: 优惠价 | K23: 优惠价 | M23: 104000 | N23: 优惠后按照104,000元结算
F25: 变更小结 | K25: 变更小结
F26: 执行前定标价格 vs. 投标阶段预中标价格 | K26: 执行后结算价格 vs. 执行前定标价格
F27: 新增需求内容 | I27: =SUMIF(明细页模板!Z$8:Z$129,F27:F30,明细页模板!Y$8:Y$129) -> 45309.387 | K27: 新增需求内容 | M27: =SUMIF(明细页模板!AP$8:AP$103,K27:K30,明细页模板!AO$8:AO$103) -> 1984.47
F28: 取消需求内容 | I28: =SUMIF(明细页模板!Z$8:Z$129,F27:F30,明细页模板!Y$8:Y$129) -> -93652.084 | K28: 取消需求内容 | M28: =SUMIF(明细页模板!AP$8:AP$103,K27:K30,明细页模板!AO$8:AO$103) -> -300
F29: 变更需求内容-导致费用增加 | I29: =SUMIF(明细页模板!Z$8:Z$129,F27:F30,明细页模板!Y$8:Y$129) -> -782.86811 | K29: 变更需求内容-导致费用增加 | M29: =SUMIF(明细页模板!AP$8:AP$103,K27:K30,明细页模板!AO$8:AO$103) -> 0
F30: 变更需求内容-导致费用减少 | I30: =SUMIF(明细页模板!Z$8:Z$129,F27:F30,明细页模板!Y$8:Y$129) -> -8342.3362 | K30: 变更需求内容-导致费用减少 | M30: =SUMIF(明细页模板!AP$8:AP$103,K27:K30,明细页模板!AO$8:AO$103) -> -2700.28

Sheet 明细页模板
A1: 报价阶段-投标阶段 | N1: 报价阶段-执行前定标阶段 | AD1: 报价阶段-执行后结算阶段
A2: 报价项目 | C2: 京东图书开学季 | N2: 报价项目 | P2: 京东图书开学季 | AD2: 报价项目 | AF2: 京东图书开学季
A3: 项目时间 | C3: 2025年8月30-31日 | N3: 项目时间 | P3: 2025年8月30-31日 | AD3: 项目时间 | AF3: 2025年8月30-31日
A4: 报价公司名称 | C4: 成都申逻商务信息咨询有限公司 | N4: 报价公司名称 | P4: 成都申逻商务信息咨询有限公司 | AD4: 报价公司名称 | AF4: 成都申逻商务信息咨询有限公司
A5: 报价人姓名 | C5: 王茜 | D5: 报价人联系电话 | E5: 18054795309 | F5: 报价人邮箱 | G5: shirly.wang@sensel.team | N5: 报价人姓名 | P5: 王茜 | Q5: 报价人联系电话 | R5: 18054795309 | S5: 报价人邮箱 | T5: shirly.wang@sensel.team | AD5: 报价人姓名 | AF5: 王茜 | AG5: 报价人联系电话 | AH5: 18054795309 | AI5: 报价人邮箱 | AJ5: shirly.wang@sensel.team
A6: 具体报价内容 | N6: 具体报价内容 | AD6: 具体报价内容
A7: 序号 | B7: 项目分项 | C7: 年框编号 *非框则为空 | D7: 项目明细 | E7: 具体明细（工艺/内容/规格） | F7: 数量 | G7: 数量单位 | H7: 时间 | I7: 时间单位 | J7: 单价 | K7: 金额 | L7: 备注 如有垫付或者要求提供凭证项，备注”提供凭证实报实销“ | N7: 序号 | O7: 项目分项 | P7: 年框编号 *非框则为空 | Q7: 项目明细 | R7: 具体明细（工艺/内容/规格） | S7: 数量 | T7: 数量单位 | U7: 时间 | V7: 时间单位 | W7: 单价 | X7: 金额 | Y7: 变更金额 | Z7: 变更状态 | AA7: 变更说明 | AB7: 备注 如有垫付或者要求提供凭证项，备注”提供凭证实报实销“ | AD7: 序号 | AE7: 项目分项 | AF7: 年框编号 *非框则为空 | AG7: 项目明细 | AH7: 具体明细（工艺/内容/规格） | AI7: 数量 | AJ7: 数量单位 | AK7: 时间 | AL7: 时间单位 | AM7: 单价 | AN7: 金额 | AO7: 变更金额 | AP7: 变更状态 | AQ7: 变更说明 | AR7: 备注 如有垫付或者要求提供凭证，请按照顺利整理相关凭证并编号，下方对应注明；凭证整体打包压缩后发送提供； 示例：凭证1-礼品购买XXX元 示例：凭证2-场地垫付XXX元
A8: 1 | B8: 指定垫付部分 | N8: 1 | O8: 指定垫付部分 | AD8: 1 | AE8: 指定垫付部分 | AO8: =X8-AN8 -> 0
A9: 2 | B9: 。。。 | N9: 2 | AD9: 2
A10: 3 | B10: 指定垫付部分小计 | C10: \ | D10: \ | E10: \ | F10: \ | G10: \ | H10: \ | I10: \ | J10: \ | K10: =SUM(K8:K9) -> 0 | N10: 3 | O10: 指定垫付部分小计 | P10: \ | Q10: \ | R10: \ | S10: \ | T10: \ | U10: \ | V10: \ | W10: \ | X10: 0 | AD10: 3 | AE10: 指定垫付部分小计 | AF10: \ | AG10: \ | AH10: \ | AI10: \ | AJ10: \ | AK10: \ | AL10: \ | AM10: \ | AO10: 0 | AP10: 0 | AQ10: 0
A11: 4 | B11: 场地租赁部分 | N11: 4 | O11: 场地租赁部分 | AD11: 4
A12: 5 | B12: 。。。 | N12: 5 | O12: 场地租赁部分 | AD12: 5
A13: 6 | B13: 场地租赁部分小计 | C13: \ | D13: \ | E13: \ | F13: \ | G13: \ | H13: \ | I13: \ | J13: \ | K13: 0 | N13: 6 | O13: 场地租赁部分小计 | P13: \ | Q13: \ | R13: \ | S13: \ | T13: \ | U13: \ | V13: \ | W13: \ | X13: 0 | AD13: 6 | AE13: 场地租赁部分小计 | AF13: \ | AG13: \ | AH13: \ | AI13: \ | AJ13: \ | AK13: \ | AL13: \ | AM13: \ | AO13: 0 | AP13: 0 | AQ13: 0
A14: 7 | B14: 场地电费支出 | E14: 场地电费，1元/度 | F14: 1 | G14: 项 | H14: 2 | I14: 天 | J14: 500 | K14: =F14*H14*J14 -> 1000 | L14: 场地电费，据实结算 | N14: 7 | O14: 场地电费支出 | R14: 场地电费，1元/度 | S14: 0 | T14: 项 | U14: 0 | V14: 天 | W14: 0 | X14: =S14*U14*W14 -> 0 | Y14: =X14-K14 -> -1000 | Z14: 取消需求内容 | AD14: 7 | AE14: 场地保险费用 | AH14: 保险采买 | AI14: 1 | AJ14: 项 | AK14: 1 | AL14: 天 | AM14: 2000 | AN14: =AI14*AK14*AM14 -> 2000 | AO14: =AN14-X15 -> 0 | AR14: 凭证12
A15: 8 | B15: 场地保险费用 | E15: 保险采买 | F15: 1 | G15: 项 | H15: 1 | I15: 天 | J15: 3000 | K15: =F15*H15*J15 -> 3000 | L15: 保险费用预留，据实结算 | N15: 8 | O15: 场地保险费用 | R15: 保险采买 | S15: 1 | T15: 项 | U15: 1 | V15: 天 | W15: 2000 | X15: =S15*U15*W15 -> 2000 | Y15: =X15-K15 -> -1000 | Z15: 变更需求内容-导致费用增加 | AB15: 提供凭证实报实销 | AD15: 8
A16: 9 | B16: 场地安评报告 | E16: 场地安评报告提供 | F16: 1 | G16: 项 | H16: 1 | I16: 天 | J16: 8000 | K16: =F16*H16*J16 -> 8000 | L16: 场地报备安评报告费用 | N16: 9 | O16: 场地安评报告 | R16: 场地安评报告提供 | S16: 0 | T16: 项 | U16: 0 | V16: 天 | W16: 0 | X16: =S16*U16*W16 -> 0 | Y16: =X16-K16 -> -8000 | Z16: 取消需求内容 | AD16: 9 | AE16: 场地杂项部分小计 | AF16: \ | AG16: \ | AH16: \ | AI16: \ | AJ16: \ | AK16: \ | AL16: \ | AM16: \ | AN16: =SUM(AN14:AN14) -> 2000 | AO16: =SUM(AO14:AO14) -> 0 | AP16: 0 | AQ16: 0
A17: 10 | B17: 。。。 | N17: 10 | O17: 场地杂项部分 | AD17: 10 | AE17: 点位地贴 | AF17: JT0807010250026 | AG17: 搭建部分-写真喷绘 | AH17: 搭建部分-写真喷绘 高清画面地贴 黑底带背胶表面覆地膜，1.5m宽幅，130g高精度喷印/裱亚膜 制作 | AI17: 124.81 | AJ17: 平方米 | AK17: 1 | AL17: 天 | AM17: 80 | AN17: =AI17*AK17*AM17 -> 9984.8 | AO17: =AN17-X20 -> 0
A18: 11 | B18: 场地杂项部分小计 | C18: \ | D18: \ | E18: \ | F18: \ | G18: \ | H18: \ | I18: \ | J18: \ | K18: =SUM(K14:K17) -> 12000 | N18: 11 | O18: 场地杂项部分小计 | P18: \ | Q18: \ | R18: \ | S18: \ | T18: \ | U18: \ | V18: \ | W18: \ | X18: =SUM(X14:X16) -> 2000 | Y18: =SUM(Y14:Y16) -> -10000 | AD18: 11 | AE18: 主dp-结构 | AF18: JT0807010100009 | AG18: 搭建部分-背景结构 | AH18: 搭建部分-背景结构 木质背板 异形单面木质背景板/木结构，表面防火板，正面裱写真，含支撑及画面 制作 | AI18: 26.4 | AJ18: 平方米 | AK18: 1 | AL18: 天 | AM18: 235.84906 | AN18: =AI18*AK18*AM18 -> 6226.4151 | AO18: =AN18-X22 -> 0
A19: 12 | B19: 点位地贴 | C19: JT0807010250023 | D19: 搭建部分-写真喷绘 | E19: 搭建部分-写真喷绘 斜纹地贴 常规规格 制作 | F19: 120 | G19: 平方米 | H19: 1 | I19: 天 | J19: 70 | K19: =F19*H19*J19 -> 8400 | L19: 地贴尺寸:12*10=120㎡ | N19: 12 | O19: 点位地贴 | P19: JT0807010250023 | Q19: 搭建部分-写真喷绘 | R19: 搭建部分-写真喷绘 斜纹地贴 常规规格 制作 | S19: 0 | T19: 平方米 | U19: 0 | V19: 天 | W19: 70 | X19: =S19*U19*W19 -> 0 | Y19: =X19-K19 -> -8400 | Z19: 取消需求内容 | AA19: 设计定稿后更新材质及尺寸 | AD19: 12 | AE19: 主dp-装饰画面 | AF19: JT0807010250017 | AG19: 搭建部分-写真喷绘 | AH19: 搭建部分-写真喷绘 写真喷绘 PVC板/裱高清,5MM板，含覆膜/常规规格 制作 | AI19: 5 | AJ19: 平方米 | AK19: 1 | AL19: 天 | AM19: 80 | AN19: =AI19*AK19*AM19 -> 400 | AO19: =AN19-X24 -> 0
A20: 13 | B20: 主dp-结构 | C20: JT0807010100010 | D20: 搭建部分-背景结构 | E20: 搭建部分-背景结构 木质背板 双面木质涂料背板/木结构，表面刷涂料，含支撑 制作 | F20: 48 | G20: 平方米 | H20: 1 | I20: 天 | J20: 295 | K20: =F20*H20*J20 -> 14160 | L20: 设计未定，尺寸预估；2*(4.2*2.5+2.5*1.2+4.2*1.2)=38.58㎡, 书本左上结构做热弯工艺,尺寸及耗材会增加,合计为48㎡ | N20: 13 | O20: 点位地贴 | P20: JT0807010250026 | Q20: 搭建部分-写真喷绘 | R20: 搭建部分-写真喷绘 高清画面地贴 黑底带背胶表面覆地膜，1.5m宽幅，130g高精度喷印/裱亚膜 制作 | S20: 124.81 | T20: 平方米 | U20: 1 | V20: 天 | W20: 80 | X20: =S20*U20*W20 -> 9984.8 | Y20: =X20-0 -> 9984.8 | Z20: 新增需求内容 | AA20: 设计定稿后更新材质及尺寸 | AB20: 大地贴：尺寸 长12.69m 宽9.52 面积计算：12.69*9.52=120.81m²； 小地贴：尺寸 长2m 宽2m 2*2=4m，小计124.81m² | AD20: 13 | AE20: 主dp-支撑 | AF20: JT0807010190017 | AG20: 搭建部分-基础结构 | AH20: 搭建部分-基础结构 钢结构 30*30方钢 制作 | AI20: 9.42 | AJ20: 米 | AK20: 1 | AL20: 天 | AM20: 39.839623 | AN20: =AI20*AK20*AM20 -> 375.28925 | AO20: =AN20-X25 -> 0
A21: 14 | B21: 主dp-画面 | C21: JT0807010250006 | D21: 搭建部分-写真喷绘 | E21: 搭建部分-写真喷绘 写真喷绘 进口3M车贴 /常规规格 制作 | F21: 38.58 | G21: 平方米 | H21: 1 | I21: 天 | J21: 60.377358 | K21: =F21*H21*J21 -> 2329.3585 | L21: 设计未定，尺寸预估；2(4.2*2.5+2.5*1+4.2*1)=35㎡ | N21: 14 | O21: 主dp-结构 | P21: JT0807010100010 | Q21: 搭建部分-背景结构 | R21: 搭建部分-背景结构 木质背板 双面木质涂料背板/木结构，表面刷涂料，含支撑 制作 | S21: 0 | T21: 平方米 | U21: 1 | V21: 天 | W21: 295 | X21: =S21*U21*W21 -> 0 | Y21: =X21-K20 -> -14160 | Z21: 取消需求内容 | AA21: 设计定稿后更新材质及尺寸 | AD21: 14 | AE21: 主dp-底座结构 | AF21: JT0807010100006 | AG21: 搭建部分-背景结构 | AH21: 搭建部分-背景结构 木质背板 异形单面木质涂料背板/木结构，表面刷涂料，含支撑 制作 | AI21: 10.56 | AJ21: 平方米 | AK21: 1 | AL21: 天 | AM21: 240 | AN21: =AI21*AK21*AM21 -> 2534.4 | AO21: =AN21-X27 -> 0
A22: 15 | B22: 主dp-装饰画面 | C22: JT0807010250017 | D22: 搭建部分-写真喷绘 | E22: 搭建部分-写真喷绘 写真喷绘 PVC板/裱高清,5MM板，含覆膜/常规规格 制作 | F22: 8 | G22: 平方米 | H22: 1 | I22: 天 | J22: 80 | K22: =F22*H22*J22 -> 640 | L22: 装饰雪弗板画面 | N22: 15 | O22: 主dp-结构 | P22: JT0807010100009 | Q22: 搭建部分-背景结构 | R22: 搭建部分-背景结构 木质背板 异形单面木质背景板/木结构，表面防火板，正面裱写真，含支撑及画面 制作 | S22: 26.4 | T22: 平方米 | U22: 1 | V22: 天 | W22: 235.84906 | X22: =S22*U22*W22 -> 6226.4151 | Y22: =X22-0 -> 6226.4151 | Z22: 新增需求内容 | AA22: 设计定稿后更新材质及尺寸 | AB22: 左侧书页：宽2.01m 高2.5m 厚度0.33m 面积计算：2×(0.6633+0.825+5.025)=13.03m² 右侧书页：宽2.07m 高2.5m 厚度0.33m 面积计算：2×(0.6831+0.825+5.175)=13.37m² 小计：13.03+13.37=26.4m² | AD22: 15 | AE22: 主dp-底座画面 | AF22: JT0807010250006 | AG22: 搭建部分-写真喷绘 | AH22: 搭建部分-写真喷绘 写真喷绘 进口3M车贴 /常规规格 制作 | AI22: 10.56 | AJ22: 平方米 | AK22: 1 | AL22: 天 | AM22: 60.377358 | AN22: =AI22*AK22*AM22 -> 637.58491 | AO22: =AN22-X28 -> 0
A23: 16 | B23: 主dp-支撑 | C23: JT0807010190017 | D23: 搭建部分-基础结构 | E23: 搭建部分-基础结构 钢结构 30*30方钢 制作 | F23: 20.1 | G23: 米 | H23: 1 | I23: 天 | J23: 39.839623 | K23: =F23*H23*J23 -> 800.77642 | L23: 钢结构支撑:3(4.2+2.5)=20.1m | N23: 16 | O23: 主dp-画面 | P23: JT0807010250006 | Q23: 搭建部分-写真喷绘 | R23: 搭建部分-写真喷绘 写真喷绘 进口3M车贴 /常规规格 制作 | S23: 0 | T23: 平方米 | U23: 0 | V23: 天 | W23: 60.377358 | X23: =S23*U23*W23 -> 0 | Y23: =X23-K21 -> -2329.3585 | Z23: 取消需求内容 | AA23: 设计定稿后更新材质及尺寸 | AD23: 16 | AE23: 互动点位1-大结构 | AF23: JT0807010100009 | AG23: 搭建部分-背景结构 | AH23: 搭建部分-背景结构 木质背板 异形单面木质背景板/木结构，表面防火板，正面裱写真，含支撑及画面 制作 | AI23: 15.46 | AJ23: 平方米 | AK23: 1 | AL23: 天 | AM23: 235.84906 | AN23: =AI23*AK23*AM23 -> 3646.2264 | AO23: =AN23-Y30 -> 0
A24: 17 | B24: 主dp-底座结构 | C24: JT0807010100010 | D24: 搭建部分-背景结构 | E24: 搭建部分-背景结构 木质背板 双面木质涂料背板/木结构，表面刷涂料，含支撑 制作 | F24: 5.2 | G24: 平方米 | H24: 1 | I24: 天 | J24: 295 | K24: =F24*H24*J24 -> 1534 | L24: 设计未定，尺寸预估，2(2*1+1*0.2+2*0.2)=5.2㎡ | N24: 17 | O24: 主dp-装饰画面 | P24: JT0807010250017 | Q24: 搭建部分-写真喷绘 | R24: 搭建部分-写真喷绘 写真喷绘 PVC板/裱高清,5MM板，含覆膜/常规规格 制作 | S24: 5 | T24: 平方米 | U24: 1 | V24: 天 | W24: 80 | X24: =S24*U24*W24 -> 400 | Y24: =X24-K22 -> -240 | Z24: 变更需求内容-导致费用减少 | AA24: 设计定稿后更新材质及尺寸 | AD24: 17 | AE24: 互动点位1-导台结构 | AF24: JT0807010100017 | AG24: 搭建部分-背景结构 | AH24: 搭建部分-背景结构 木质背板 单面木质背板/木结构 表面防火板，正面裱写真，含支撑及画面 制作 | AI24: 16.21 | AJ24: 平方米 | AK24: 1 | AL24: 天 | AM24: 187 | AN24: =AI24*AK24*AM24 -> 3031.27 | AO24: =AN24-X33 -> 0
A25: 18 | B25: 主dp-底座画面 | C25: JT0807010250006 | D25: 搭建部分-写真喷绘 | E25: 搭建部分-写真喷绘 写真喷绘 进口3M车贴 /常规规格 制作 | F25: 5.2 | G25: 平方米 | H25: 1 | I25: 天 | J25: 60.377358 | K25: =F25*H25*J25 -> 313.96226 | L25: 设计未定，尺寸预估 | N25: 18 | O25: 主dp-支撑 | P25: JT0807010190017 | Q25: 搭建部分-基础结构 | R25: 搭建部分-基础结构 钢结构 30*30方钢 制作 | S25: 9.42 | T25: 米 | U25: 1 | V25: 天 | W25: 39.839623 | X25: =S25*U25*W25 -> 375.28925 | Y25: =X25-K23 -> -425.48717 | Z25: 变更需求内容-导致费用减少 | AA25: 设计定稿后更新材质及尺寸 | AB25: 横杆2.2m*2+竖杆2.51m*2=9.42m | AD25: 18 | AE25: 互动点位1-装饰结构 | AF25: JT0807010100009 | AG25: 搭建部分-背景结构 | AH25: 搭建部分-背景结构 木质背板 异形单面木质背景板/木结构，表面防火板，正面裱写真，含支撑及画面 制作 | AI25: 9.28 | AJ25: 平方米 | AK25: 1 | AL25: 天 | AM25: 235.84906 | AN25: =AI25*AK25*AM25 -> 2188.6792 | AO25: =AN25-X35 -> 0
A26: 19 | B26: 互动点位1-结构 | C26: JT0807010100010 | D26: 搭建部分-背景结构 | E26: 搭建部分-背景结构 木质背板 双面木质涂料背板/木结构，表面刷涂料，含支撑 制作 | F26: 33.7 | G26: 平方米 | H26: 1 | I26: 天 | J26: 295 | K26: =F26*H26*J26 -> 9941.5 | L26: 2*(4.5*2.5+2.5*0.8+4.5*0.8)=33.7㎡ | N26: 19 | O26: 主dp-底座结构 | P26: JT0807010100010 | Q26: 搭建部分-背景结构 | R26: 搭建部分-背景结构 木质背板 双面木质涂料背板/木结构，表面刷涂料，含支撑 制作 | S26: 0 | T26: 平方米 | U26: 1 | V26: 天 | W26: 295 | X26: =S26*U26*W26 -> 0 | Y26: =X26-K24 -> -1534 | Z26: 取消需求内容 | AA26: 设计定稿后更新材质及尺寸 | AD26: 19 | AE26: 互动点位1-pvc画面 | AF26: JT0807010250017 | AG26: 搭建部分-写真喷绘 | AH26: 搭建部分-写真喷绘 写真喷绘 PVC板/裱高清,5MM板，含覆膜/常规规格 制作 | AI26: 1.49 | AJ26: 平方米 | AK26: 1 | AL26: 天 | AM26: 80 | AN26: =AI26*AK26*AM26 -> 119.2 | AO26: =AN26-X36 -> 0
A27: 20 | B27: 互动点位1-画面 | C27: JT0807010250006 | D27: 搭建部分-写真喷绘 | E27: 搭建部分-写真喷绘 写真喷绘 进口3M车贴 /常规规格 制作 | F27: 33.7 | G27: 平方米 | H27: 1 | I27: 天 | J27: 60.377358 | K27: =F27*H27*J27 -> 2034.717 | L27: 2*(4.5*2.5+2.5*0.8+4.5*0.8)=33.7㎡ | N27: 20 | O27: 主dp-底座结构 | P27: JT0807010100006 | Q27: 搭建部分-背景结构 | R27: 搭建部分-背景结构 木质背板 异形单面木质涂料背板/木结构，表面刷涂料，含支撑 制作 | S27: 10.56 | T27: 平方米 | U27: 1 | V27: 天 | W27: 240 | X27: =S27*U27*W27 -> 2534.4 | Y27: =X27-0 -> 2534.4 | Z27: 新增需求内容 | AA27: 设计定稿后更新材质及尺寸 | AB27: 尺寸:长2m 宽2m 高度0.1m 面积计算：2(2.2*2.2+2.2*0.1+2.2*0.1)=10.56㎡ | AD27: 20 | AE27: 互动点位1-立体字 | AF27: JT0807010210013 | AG27: 搭建部分-立体字 | AH27: 搭建部分-立体字 PVC立体字 常规材质/厚5MM ，高度300MM-600MM以内 制作 | AI27: 1.8 | AJ27: 延米 | AK27: 1 | AL27: 天 | AM27: 139.62 | AN27: =AI27*AK27*AM27 -> 251.316 | AO27: =AN27-X37 -> 0
A28: 21 | B28: 互动点位1-导台画面 | C28: JT0807010250006 | D28: 搭建部分-写真喷绘 | E28: 搭建部分-写真喷绘 写真喷绘 进口3M车贴 /常规规格 制作 | F28: 8 | G28: 平方米 | H28: 1 | I28: 天 | J28: 60.377358 | K28: =F28*H28*J28 -> 483.01887 | L28: 导台画面 | N28: 21 | O28: 主dp-底座画面 | P28: JT0807010250006 | Q28: 搭建部分-写真喷绘 | R28: 搭建部分-写真喷绘 写真喷绘 进口3M车贴 /常规规格 制作 | S28: 10.56 | T28: 平方米 | U28: 1 | V28: 天 | W28: 60.377358 | X28: =S28*U28*W28 -> 637.58491 | Y28: =X28-K25 -> 323.62264 | Z28: 变更需求内容-导致费用增加 | AA28: 设计定稿后更新材质及尺寸 | AB28: 尺寸:长2m 宽2m 高度0.1m 面积计算：2(2.2*2.2+2.2*0.1+2.2*0.1)=10.56㎡ | AD28: 21 | AE28: 互动点位2-结构 | AF28: JT0807010100009 | AG28: 搭建部分-背景结构 | AH28: 搭建部分-背景结构 木质背板 异形单面木质背景板/木结构，表面防火板，正面裱写真，含支撑及画面 制作 | AI28: 24.26 | AJ28: 平方米 | AK28: 1 | AL28: 天 | AM28: 235.84906 | AN28: =AI28*AK28*AM28 -> 5721.6981 | AO28: =AN28-X39 -> 0
A29: 22 | B29: 互动点位1-导台结构 | C29: JT0807010100010 | D29: 搭建部分-背景结构 | E29: 搭建部分-背景结构 木质背板 双面木质涂料背板/木结构，表面刷涂料，含支撑 制作 | F29: 8 | G29: 平方米 | H29: 1 | I29: 天 | J29: 295 | K29: =F29*H29*J29 -> 2360 | L29: 导台结构 | N29: 22 | O29: 互动点位1-大结构 | P29: JT0807010100010 | Q29: 搭建部分-背景结构 | R29: 搭建部分-背景结构 木质背板 双面木质涂料背板/木结构，表面刷涂料，含支撑 制作 | S29: 0 | T29: 平方米 | U29: 1 | V29: 天 | W29: 295 | X29: =S29*U29*W29 -> 0 | Y29: =X29-K26 -> -9941.5 | Z29: 取消需求内容 | AA29: 设计定稿后更新材质及尺寸 | AD29: 22 | AE29: 互动点位2-屋檐结构 | AF29: JT0807010100009 | AG29: 搭建部分-背景结构 | AH29: 搭建部分-背景结构 木质背板 异形单面木质背景板/木结构，表面防火板，正面裱写真，含支撑及画面 制作 | AI29: 12.46 | AJ29: 平方米 | AK29: 1 | AL29: 天 | AM29: 235.84906 | AN29: =AI29*AK29*AM29 -> 2938.6792 | AO29: =AN29-X43 -> 0
A30: 23 | B30: 互动点位1-导台支撑 | C30: JT0807010190017 | D30: 搭建部分-基础结构 | E30: 搭建部分-基础结构 钢结构 30*30方钢 制作 | F30: 10 | G30: 米 | H30: 1 | I30: 天 | J30: 39.839623 | K30: =F30*H30*J30 -> 398.39623 | L30: 支撑4*2+2=10m | N30: 23 | O30: 互动点位1-大结构 | P30: JT0807010100009 | Q30: 搭建部分-背景结构 | R30: 搭建部分-背景结构 木质背板 异形单面木质背景板/木结构，表面防火板，正面裱写真，含支撑及画面 制作 | S30: 15.46 | T30: 平方米 | U30: 1 | V30: 天 | W30: 235.84906 | X30: =S30*U30*W30 -> 3646.2264 | Y30: =X30-0 -> 3646.2264 | Z30: 新增需求内容 | AA30: 设计定稿后更新材质及尺寸 | AB30: 尺寸：3.5m宽 1.9m高 厚度0.2m 面积计算：2×(6.65+0.38+0.7)=15.46m² | AD30: 23 | AE30: 互动点位2-互动导台 | AF30: JT0807010270004 | AG30: 搭建部分-制作物 | AH30: 搭建部分-制作物 展台/接待台 木结构防火板或裱画面, 弧形 ,做门带锁/ 规格高1m以下, 径深60cm以内 制作 | AI30: 2.2 | AJ30: 延米 | AK30: 1 | AL30: 天 | AM30: 750 | AN30: =AI30*AK30*AM30 -> 1650 | AO30: =AN30-X44 -> 0
A31: 24 | B31: 互动点位1-装饰画面 | C31: JT0807010250017 | D31: 搭建部分-写真喷绘 | E31: 搭建部分-写真喷绘 写真喷绘 PVC板/裱高清,5MM板，含覆膜/常规规格 制作 | F31: 5 | G31: 平方米 | H31: 1 | I31: 天 | J31: 80 | K31: =F31*H31*J31 -> 400 | L31: 装饰雪弗板画面 | N31: 24 | O31: 互动点位1-画面 | P31: JT0807010250006 | Q31: 搭建部分-写真喷绘 | R31: 搭建部分-写真喷绘 写真喷绘 进口3M车贴 /常规规格 制作 | S31: 0 | T31: 平方米 | U31: 1 | V31: 天 | W31: 60.377358 | X31: =S31*U31*W31 -> 0 | Y31: =X31-K27 -> -2034.717 | Z31: 取消需求内容 | AA31: 设计定稿后更新材质及尺寸 | AD31: 24 | AE31: 互动点位2-装饰pvc | AF31: JT0807010250017 | AG31: 搭建部分-写真喷绘 | AH31: 搭建部分-写真喷绘 写真喷绘 PVC板/裱高清,5MM板，含覆膜/常规规格 制作 | AI31: 2.52 | AJ31: 平方米 | AK31: 1 | AL31: 天 | AM31: 80 | AN31: =AI31*AK31*AM31 -> 201.6 | AO31: =AN31-X45 -> 0
A32: 25 | B32: 互动点位1-pvc立体字 | C32: JT0807010210015 | D32: 搭建部分-立体字 | E32: 搭建部分-立体字 PVC立体字 常规材质/厚3MM ，高度300MM-600MM以内 制作 | F32: 4 | G32: 延米 | H32: 1 | I32: 天 | J32: 100 | K32: =F32*H32*J32 -> 400 | L32: pvc立体字 | N32: 25 | O32: 互动点位1-导台结构 | P32: JT0807010100010 | Q32: 搭建部分-背景结构 | R32: 搭建部分-背景结构 木质背板 双面木质涂料背板/木结构，表面刷涂料，含支撑 制作 | S32: 0 | T32: 平方米 | U32: 1 | V32: 天 | W32: 295 | X32: =S32*U32*W32 -> 0 | Y32: =X32-K29 -> -2360 | Z32: 取消需求内容 | AA32: 设计定稿后更新材质及尺寸 | AD32: 25 | AE32: 互动点位2-京东图书立体字 | AF32: JT0807010210013 | AG32: 搭建部分-立体字 | AH32: 搭建部分-立体字 PVC立体字 常规材质/厚5MM ，高度300MM-600MM以内 制作 | AI32: 3.26 | AJ32: 延米 | AK32: 1 | AL32: 天 | AM32: 139.62 | AN32: =AI32*AK32*AM32 -> 455.1612 | AO32: =AN32-X48 -> 0
A33: 26 | B33: 互动点位2-背板结构 | C33: JT0807010100010 | D33: 搭建部分-背景结构 | E33: 搭建部分-背景结构 木质背板 双面木质涂料背板/木结构，表面刷涂料，含支撑 制作 | F33: 35 | G33: 平方米 | H33: 1 | I33: 天 | J33: 295 | K33: =F33*H33*J33 -> 10325 | L33: 设计未定，尺寸预估；2*(5*2.3+2.3*0.8+0.8*5)=30.68㎡，预估损耗共计35㎡ | N33: 26 | O33: 互动点位1-导台结构 | P33: JT0807010100017 | Q33: 搭建部分-背景结构 | R33: 搭建部分-背景结构 木质背板 单面木质背板/木结构 表面防火板，正面裱写真，含支撑及画面 制作 | S33: 16.21 | T33: 平方米 | U33: 1 | V33: 天 | W33: 187 | X33: =S33*U33*W33 -> 3031.27 | Y33: =X33-0 -> 3031.27 | Z33: 新增需求内容 | AA33: 设计定稿后更新材质及尺寸 | AB33: 横面板尺寸：长3.3m 宽 1.9m高 厚度0.08m 面积计算：2×(6.27+0.264+0.152)=13.72 竖板尺寸：高0.82m 宽0.4m 厚度0.07m 3组 2×(0.328+0.0574+0.028）=0.83*3=2.49m² ， 总计：16.21m² | AD33: 26 | AE33: 书适圈点位-画面 | AF33: JT0807010250017 | AG33: 搭建部分-写真喷绘 | AH33: 搭建部分-写真喷绘 写真喷绘 PVC板/裱高清,5MM板，含覆膜/常规规格 制作 | AI33: 4.22 | AJ33: 平方米 | AK33: 1 | AL33: 天 | AM33: 80 | AN33: =AI33*AK33*AM33 -> 337.6 | AO33: =AN33-X49 -> 0
A34: 27 | B34: 互动点位2-背板画面 | C34: JT0807010250006 | D34: 搭建部分-写真喷绘 | E34: 搭建部分-写真喷绘 写真喷绘 进口3M车贴 /常规规格 制作 | F34: 35 | G34: 平方米 | H34: 1 | I34: 天 | J34: 60.377358 | K34: =F34*H34*J34 -> 2113.2075 | L34: 2*(5*2.3+2.3*0.8+0.8*5)=30.68㎡，预估损耗共计35㎡ | N34: 27 | O34: 互动点位1-导台画面 | P34: JT0807010250006 | Q34: 搭建部分-写真喷绘 | R34: 搭建部分-写真喷绘 写真喷绘 进口3M车贴 /常规规格 制作 | S34: 0 | T34: 平方米 | U34: 1 | V34: 天 | W34: 60.377358 | X34: =S34*U34*W34 -> 0 | Y34: =X34-K28 -> -483.01887 | Z34: 取消需求内容 | AA34: 设计定稿后更新材质及尺寸 | AD34: 27 | AE34: 书适圈点位-支撑 | AF34: JT0807010190017 | AG34: 搭建部分-基础结构 | AH34: 搭建部分-基础结构 钢结构 30*30方钢 制作 | AI34: 3.05 | AJ34: 米 | AK34: 1 | AL34: 天 | AM34: 39.839623 | AN34: =AI34*AK34*AM34 -> 121.51085 | AO34: =AN34-X50 -> 0
A35: 28 | B35: 互动点位2-背板支撑 | C35: JT0807010190017 | D35: 搭建部分-基础结构 | E35: 搭建部分-基础结构 钢结构 30*30方钢 制作 | F35: 14.6 | G35: 米 | H35: 1 | I35: 天 | J35: 39.839623 | K35: =F35*H35*J35 -> 581.65849 | L35: 5*2+2.3*2=14.6m | N35: 28 | O35: 互动点位1-装饰结构 | P35: JT0807010100009 | Q35: 搭建部分-背景结构 | R35: 搭建部分-背景结构 木质背板 异形单面木质背景板/木结构，表面防火板，正面裱写真，含支撑及画面 制作 | S35: 9.28 | T35: 平方米 | U35: 1 | V35: 天 | W35: 235.84906 | X35: =S35*U35*W35 -> 2188.6792 | Y35: =X35-0 -> 2188.6792 | Z35: 新增需求内容 | AA35: 设计定稿后更新材质及尺寸 | AB35: 尺寸:高1.9m 宽1.85m 厚度0.3m 2×(3.515+0.57+0.555)=9.28m² | AD35: 28 | AE35: 书适圈点位-配重 | AF35: JT0807010100017 | AG35: 搭建部分-背景结构 | AH35: 搭建部分-背景结构 木质背板 单面木质背板/木结构 表面防火板，正面裱写真，含支撑及画面 制作 | AI35: 1.42 | AJ35: 平方米 | AK35: 1 | AL35: 天 | AM35: 187 | AN35: =AI35*AK35*AM35 -> 265.54 | AO35: =AN35-X51 -> 0
A36: 29 | B36: 互动点位2-屋檐结构 | C36: JT0807010100010 | D36: 搭建部分-背景结构 | E36: 搭建部分-背景结构 木质背板 双面木质涂料背板/木结构，表面刷涂料，含支撑 制作 | F36: 10 | G36: 平方米 | H36: 1 | I36: 天 | J36: 295 | K36: =F36*H36*J36 -> 2950 | L36: 2*(2*1+1*0.5+2*0.5)=7㎡,该结构正反两面中间需要加固处理,合计为10㎡ | N36: 29 | O36: 互动点位1-pvc画面 | P36: JT0807010250017 | Q36: 搭建部分-写真喷绘 | R36: 搭建部分-写真喷绘 写真喷绘 PVC板/裱高清,5MM板，含覆膜/常规规格 制作 | S36: 1.49 | T36: 平方米 | U36: 1 | V36: 天 | W36: 80 | X36: =S36*U36*W36 -> 119.2 | Y36: =X36-K31 -> -280.8 | Z36: 变更需求内容-导致费用减少 | AA36: 设计定稿后更新材质及尺寸 | AB36: 尺寸:1.2*0.43+0.88*0.64+0.61*0.67=1.49㎡ | AD36: 29 | AE36: 入口处-结构 | AF36: JT0807010100009 | AG36: 搭建部分-背景结构 | AH36: 搭建部分-背景结构 木质背板 异形单面木质背景板/木结构，表面防火板，正面裱写真，含支撑及画面 制作 | AI36: 9.9 | AJ36: 平方米 | AK36: 1 | AL36: 天 | AM36: 235.84906 | AN36: =AI36*AK36*AM36 -> 2334.9057 | AO36: =AN36-X54 -> 0
A37: 30 | B37: 互动点位2-屋檐画面 | C37: JT0807010250006 | D37: 搭建部分-写真喷绘 | E37: 搭建部分-写真喷绘 写真喷绘 进口3M车贴 /常规规格 制作 | F37: 7 | G37: 平方米 | H37: 1 | I37: 天 | J37: 60.377358 | K37: =F37*H37*J37 -> 422.64151 | L37: 支撑4*2+2=10m | N37: 30 | O37: 互动点位1-立体字 | P37: JT0807010210013 | Q37: 搭建部分-立体字 | R37: 搭建部分-立体字 PVC立体字 常规材质/厚5MM ，高度300MM-600MM以内 制作 | S37: 1.8 | T37: 延米 | U37: 1 | V37: 天 | W37: 139.62 | X37: =S37*U37*W37 -> 251.316 | Y37: =X37-K32 -> -148.684 | Z37: 变更需求内容-导致费用减少 | AA37: 设计定稿后更新材质及尺寸 | AB37: 立体字尺寸:1.8m | AD37: 30 | AE37: 入口处-互动导台 | AF37: JT0807010270006 | AG37: 搭建部分-制作物 | AH37: 搭建部分-制作物 展台/接待台 木结构防火板或裱画面 ,高低柜形, 做门带锁/规格 高1m以下, 径深60cm以内 制作 | AI37: 1.2 | AJ37: 延米 | AK37: 1 | AL37: 天 | AM37: 750 | AN37: =AI37*AK37*AM37 -> 900 | AO37: =AN37-X59 -> 0
A38: 31 | B38: 互动点位2-互动导台 | C38: JT0807010270004 | D38: 搭建部分-制作物 | E38: 搭建部分-制作物 展台/接待台 木结构防火板或裱画面, 弧形 ,做门带锁/ 规格高1m以下, 径深60cm以内 制作 | F38: 2.2 | G38: 延米 | H38: 1 | I38: 天 | J38: 750 | K38: =F38*H38*J38 -> 1650 | L38: 互动导台长1.2m，预估损耗2.2m | N38: 31 | O38: 互动点位2-结构 | P38: JT0807010100010 | Q38: 搭建部分-背景结构 | R38: 搭建部分-背景结构 木质背板 双面木质涂料背板/木结构，表面刷涂料，含支撑 制作 | S38: 0 | T38: 平方米 | U38: 1 | V38: 天 | W38: 295 | X38: =S38*U38*W38 -> 0 | Y38: =X38-K33 -> -10325 | Z38: 取消需求内容 | AA38: 设计定稿后更新材质及尺寸 | AD38: 31 | AE38: 氛围物料-镜子结构+画面 | AF38: JT0807010100009 | AG38: 搭建部分-背景结构 | AH38: 搭建部分-背景结构 木质背板 异形单面木质背景板/木结构，表面防火板，正面裱写真，含支撑及画面 制作 | AI38: 11.04 | AJ38: 平方米 | AK38: 1 | AL38: 天 | AM38: 235.84906 | AN38: =AI38*AK38*AM38 -> 2603.7736 | AO38: =AN38-X62 -> 0
A39: 32 | B39: 互动点位2-导台底部结构 | C39: JT0807010100010 | D39: 搭建部分-背景结构 | E39: 搭建部分-背景结构 木质背板 双面木质涂料背板/木结构，表面刷涂料，含支撑 制作 | F39: 10.56 | G39: 平方米 | H39: 1 | I39: 天 | J39: 295 | K39: =F39*H39*J39 -> 3115.2 | L39: 2*(2.2*2.2+2.2*0.1+2.2*0.1)=10.56㎡ | N39: 32 | O39: 互动点位2-结构 | P39: JT0807010100009 | Q39: 搭建部分-背景结构 | R39: 搭建部分-背景结构 木质背板 异形单面木质背景板/木结构，表面防火板，正面裱写真，含支撑及画面 制作 | S39: 24.26 | T39: 平方米 | U39: 1 | V39: 天 | W39: 235.84906 | X39: =S39*U39*W39 -> 5721.6981 | Y39: =X39-0 -> 5721.6981 | Z39: 新增需求内容 | AA39: 设计定稿后更新材质及尺寸 | AB39: 尺寸：宽3.4m 高2.7m 厚0.5m 面积计算：2(3.4*2.7+3.4*0.5+2.7*0.5)=24.26㎡ | AD39: 32 | AE39: 氛围物料-镜子底座结构 | AF39: JT0807010100009 | AG39: 搭建部分-背景结构 | AH39: 搭建部分-背景结构 木质背板 异形单面木质背景板/木结构，表面防火板，正面裱写真，含支撑及画面 制作 | AI39: 5.96 | AJ39: 平方米 | AK39: 1 | AL39: 天 | AM39: 235.84906 | AN39: =AI39*AK39*AM39 -> 1405.6604 | AO39: =AN39-X65 -> 0
A40: 33 | B40: 互动点位2-导台底部画面 | C40: JT0807010250006 | D40: 搭建部分-写真喷绘 | E40: 搭建部分-写真喷绘 写真喷绘 进口3M车贴 /常规规格 制作 | F40: 10.56 | G40: 平方米 | H40: 1 | I40: 天 | J40: 60.377358 | K40: =F40*H40*J40 -> 637.58491 | L40: 2*(2.2*2.2+2.2*0.1+2.2*0.1)=10.56㎡ | N40: 33 | O40: 互动点位2-画面 | P40: JT0807010250006 | Q40: 搭建部分-写真喷绘 | R40: 搭建部分-写真喷绘 写真喷绘 进口3M车贴 /常规规格 制作 | S40: 0 | T40: 平方米 | U40: 1 | V40: 天 | W40: 60.377358 | X40: =S40*U40*W40 -> 0 | Y40: =X40-K34 -> -2113.2075 | Z40: 取消需求内容 | AA40: 设计定稿后更新材质及尺寸 | AD40: 33 | AE40: 氛围物料-灯管喷漆 | AF40: JT0807010190008 | AG40: 搭建部分-基础结构 | AH40: 搭建部分-基础结构 喷漆 三层喷漆，金属漆 制作 | AI40: 1 | AJ40: 平方米 | AK40: 1 | AL40: 套 | AM40: 101.885 | AN40: =AI40*AK40*AM40 -> 101.885 | AO40: =AN40-X66 -> 0
...
